Traceback (most recent call last):
  File "/lustre06/project/6084435/ksjoe30/ubc/lib/python3.10/site-packages/urllib3/connection.py", line 174, in _new_conn
    conn = connection.create_connection(
  File "/lustre06/project/6084435/ksjoe30/ubc/lib/python3.10/site-packages/urllib3/util/connection.py", line 95, in create_connection
    raise err
  File "/lustre06/project/6084435/ksjoe30/ubc/lib/python3.10/site-packages/urllib3/util/connection.py", line 85, in create_connection
    sock.connect(sa)
OSError: [Errno 101] Network is unreachable

During handling of the above exception, another exception occurred:

Traceback (most recent call last):
  File "/lustre06/project/6084435/ksjoe30/ubc/lib/python3.10/site-packages/urllib3/connectionpool.py", line 714, in urlopen
    httplib_response = self._make_request(
  File "/lustre06/project/6084435/ksjoe30/ubc/lib/python3.10/site-packages/urllib3/connectionpool.py", line 403, in _make_request
    self._validate_conn(conn)
  File "/lustre06/project/6084435/ksjoe30/ubc/lib/python3.10/site-packages/urllib3/connectionpool.py", line 1053, in _validate_conn
    conn.connect()
  File "/lustre06/project/6084435/ksjoe30/ubc/lib/python3.10/site-packages/urllib3/connection.py", line 363, in connect
    self.sock = conn = self._new_conn()
  File "/lustre06/project/6084435/ksjoe30/ubc/lib/python3.10/site-packages/urllib3/connection.py", line 186, in _new_conn
    raise NewConnectionError(
urllib3.exceptions.NewConnectionError: <urllib3.connection.HTTPSConnection object at 0x1508b824cc70>: Failed to establish a new connection: [Errno 101] Network is unreachable

During handling of the above exception, another exception occurred:

Traceback (most recent call last):
  File "/lustre06/project/6084435/ksjoe30/ubc/lib/python3.10/site-packages/requests/adapters.py", line 486, in send
    resp = conn.urlopen(
  File "/lustre06/project/6084435/ksjoe30/ubc/lib/python3.10/site-packages/urllib3/connectionpool.py", line 798, in urlopen
    retries = retries.increment(
  File "/lustre06/project/6084435/ksjoe30/ubc/lib/python3.10/site-packages/urllib3/util/retry.py", line 592, in increment
    raise MaxRetryError(_pool, url, error or ResponseError(cause))
urllib3.exceptions.MaxRetryError: HTTPSConnectionPool(host='huggingface.co', port=443): Max retries exceeded with url: /api/models/sentence-transformers/stsb-distilbert-base (Caused by NewConnectionError('<urllib3.connection.HTTPSConnection object at 0x1508b824cc70>: Failed to establish a new connection: [Errno 101] Network is unreachable'))

During handling of the above exception, another exception occurred:

Traceback (most recent call last):
  File "/lustre06/project/6084435/ksjoe30/aied-cods-comad/src/training_constrastiveLoss.py", line 15, in <module>
    model = SentenceTransformer('stsb-distilbert-base')
  File "/lustre06/project/6084435/ksjoe30/ubc/lib/python3.10/site-packages/sentence_transformers/SentenceTransformer.py", line 87, in __init__
    snapshot_download(model_name_or_path,
  File "/lustre06/project/6084435/ksjoe30/ubc/lib/python3.10/site-packages/sentence_transformers/util.py", line 442, in snapshot_download
    model_info = _api.model_info(repo_id=repo_id, revision=revision, token=token)
  File "/lustre06/project/6084435/ksjoe30/ubc/lib/python3.10/site-packages/huggingface_hub/utils/_validators.py", line 118, in _inner_fn
    return fn(*args, **kwargs)
  File "/lustre06/project/6084435/ksjoe30/ubc/lib/python3.10/site-packages/huggingface_hub/hf_api.py", line 1677, in model_info
    r = get_session().get(path, headers=headers, timeout=timeout, params=params)
  File "/lustre06/project/6084435/ksjoe30/ubc/lib/python3.10/site-packages/requests/sessions.py", line 602, in get
    return self.request("GET", url, **kwargs)
  File "/lustre06/project/6084435/ksjoe30/ubc/lib/python3.10/site-packages/requests/sessions.py", line 589, in request
    resp = self.send(prep, **send_kwargs)
  File "/lustre06/project/6084435/ksjoe30/ubc/lib/python3.10/site-packages/requests/sessions.py", line 703, in send
    r = adapter.send(request, **kwargs)
  File "/lustre06/project/6084435/ksjoe30/ubc/lib/python3.10/site-packages/huggingface_hub/utils/_http.py", line 63, in send
    return super().send(request, *args, **kwargs)
  File "/lustre06/project/6084435/ksjoe30/ubc/lib/python3.10/site-packages/requests/adapters.py", line 519, in send
    raise ConnectionError(e, request=request)
requests.exceptions.ConnectionError: (MaxRetryError("HTTPSConnectionPool(host='huggingface.co', port=443): Max retries exceeded with url: /api/models/sentence-transformers/stsb-distilbert-base (Caused by NewConnectionError('<urllib3.connection.HTTPSConnection object at 0x1508b824cc70>: Failed to establish a new connection: [Errno 101] Network is unreachable'))"), '(Request ID: 0d0728e0-0010-498c-a434-3d7383e21eaf)')
